Workbook

Sheet Criba
A1: Nivel | B1: Nº | C1: Obra | D1: Título en español | E1: Autor | F1: Año | G1: Tipo | H1: Género | I1: Estación | J1: Por qué está aquí | K1: ¿Nos lo quedamos? | L1: Vicen | M1: Andrea
A2: 1 · Imprescindible | B2: 1 | C2: 1984 | E2: George Orwell | F2: 1949 | G2: Novela | H2: Distopía | I2: Invierno | J2: Canon: obra clave de la literatura | K2: Sí | L2: Leído | M2: Leído
A3: 1 · Imprescindible | B3: 6 | C3: A Confederacy of Dunces | D3: La conjura de los necios | E3: John Kennedy Toole | F3: 1980 | G3: Novela | H3: Comedia / sátira | I3: Verano | J3: Canon: obra clave de la literatura | L3: Leído
A4: 1 · Imprescindible | B4: 13 | C4: A Room of One's Own | D4: Una habitación propia | E4: Virginia Woolf | F4: 1929 | G4: Ensayo | H4: Ensayo feminista | I4: Otoño | J4: Canon: obra clave de la literatura | K4: Sí | L4: Leído | M4: Pendiente · en casa
A5: 1 · Imprescindible | B5: 22 | C5: Anna Karenina | D5: Ana Karenina | E5: León Tolstói | F5: 1878 | G5: Novela | H5: Clásico / drama romántico | I5: Invierno | J5: Canon: obra clave de la literatura | K5: Sí | L5: Pendiente · le interesa | M5: Pendiente · le interesa
A6: 1 · Imprescindible | B6: 25 | C6: As I Lay Dying | D6: Mientras agonizo | E6: William Faulkner | F6: 1930 | G6: Novela | H6: Modernismo / gótico sureño | I6: Verano | J6: Canon: obra clave de la literatura
A7: 1 · Imprescindible | B7: 32 | C7: Beloved | E7: Toni Morrison | F7: 1987 | G7: Novela | H7: Histórica / gótico | I7: Invierno | J7: Canon: obra clave de la literatura
A8: 1 · Imprescindible | B8: 35 | C8: Brave New World | D8: Un mundo feliz | E8: Aldous Huxley | F8: 1932 | G8: Novela | H8: Distopía | I8: Primavera | J8: Canon: obra clave de la literatura | K8: Sí | L8: Leído | M8: Pendiente · le interesa
A9: 1 · Imprescindible | B9: 38 | C9: Candide | D9: Cándido, o el optimismo | E9: Voltaire | F9: 1759 | G9: Novela | H9: Sátira filosófica | I9: Primavera | J9: Canon: obra clave de la literatura
A10: 1 · Imprescindible | B10: 40 | C10: Catch-22 | D10: Trampa 22 | E10: Joseph Heller | F10: 1961 | G10: Novela | H10: Sátira bélica | I10: Verano | J10: Canon: obra clave de la literatura
A11: 1 · Imprescindible | B11: 47 | C11: Crime and Punishment | D11: Crimen y castigo | E11: Fiódor Dostoievski | F11: 1866 | G11: Novela | H11: Psicológica | I11: Verano | J11: Canon: obra clave de la literatura | K11: Sí | L11: Leyendo | M11: Leyendo
A12: 1 · Imprescindible | B12: 57 | C12: Don Quixote | D12: Don Quijote de la Mancha | E12: Miguel de Cervantes | F12: 1605–1615 | G12: Novela | H12: Clásico / parodia caballeresca | I12: Verano | J12: Obligado, y en versión original | K12: Sí | M12: Pendiente · le interesa
A13: 1 · Imprescindible | B13: 74 | C13: Fahrenheit 451 | E13: Ray Bradbury | F13: 1953 | G13: Novela | H13: Distopía / ciencia ficción | I13: Otoño | J13: Libro sobre leer libros, en clave de distopía | K13: Sí | L13: Leído | M13: Leído
A14: 1 · Imprescindible | B14: 82 | C14: Frankenstein | D14: Frankenstein o el moderno Prometeo | E14: Mary Shelley | F14: 1818 | G14: Novela | H14: Gótico / ciencia ficción | I14: Invierno | J14: Canon: obra clave de la literatura | K14: Sí | L14: Leído | M14: Leído
A15: 1 · Imprescindible | B15: 92 | C15: Great Expectations | D15: Grandes esperanzas | E15: Charles Dickens | F15: 1861 | G15: Novela | H15: Bildungsroman | I15: Invierno | J15: Canon: obra clave de la literatura | K15: Sí | L15: Leído | M15: Pendiente · le interesa
A16: 1 · Imprescindible | B16: 93 | C16: Hamlet | E16: William Shakespeare | F16: c. 1600 | G16: Teatro | H16: Tragedia | I16: Invierno | J16: Canon: obra clave de la literatura | K16: Sí | L16: Leído | M16: Pendiente · le interesa
A17: 1 · Imprescindible | B17: 98 | C17: Heart of Darkness | D17: El corazón de las tinieblas | E17: Joseph Conrad | F17: 1899 | G17: Novela corta | H17: Clásico / colonialismo | I17: Verano | J17: Canon: obra clave de la literatura
A18: 1 · Imprescindible | B18: 111 | C18: In Cold Blood | D18: A sangre fría | E18: Truman Capote | F18: 1966 | G18: No ficción | H18: True crime / novela de no ficción | I18: Otoño | J18: Canon: obra clave de la literatura | K18: Sí | M18: Pendiente · le interesa
A19: 1 · Imprescindible | B19: 116 | C19: Jane Eyre | E19: Charlotte Brontë | F19: 1847 | G19: Novela | H19: Gótico / romance | I19: Otoño | J19: Canon: obra clave de la literatura | K19: Sí | M19: Pendiente · en casa
A20: 1 · Imprescindible | B20: 128 | C20: Lord of the Flies | D20: El señor de las moscas | E20: William Golding | F20: 1954 | G20: Novela | H20: Alegoría | I20: Verano | J20: Canon: obra clave de la literatura | K20: Sí | L20: Leído | M20: Pendiente · le interesa
A21: 1 · Imprescindible | B21: 129 | C21: Macbeth | E21: William Shakespeare | F21: c. 1606 | G21: Teatro | H21: Tragedia | I21: Invierno | J21: Canon: obra clave de la literatura | K21: Sí | M21: Pendiente · le interesa
A22: 1 · Imprescindible | B22: 130 | C22: Madame Bovary | E22: Gustave Flaubert | F22: 1857 | G22: Novela | H22: Realismo | I22: Otoño | J22: Canon: obra clave de la literatura | K22: Sí | M22: Pendiente · en casa
A23: 1 · Imprescindible | B23: 137 | C23: Moby-Dick | D23: Moby Dick | E23: Herman Melville | F23: 1851 | G23: Novela | H23: Aventura / clásico | I23: Invierno | J23: Canon: obra clave de la literatura | K23: Sí | L23: Leído | M23: Pendiente · le interesa
A24: 1 · Imprescindible | B24: 140 | C24: Mrs. Dalloway | D24: La señora Dalloway | E24: Virginia Woolf | F24: 1925 | G24: Novela | H24: Modernismo | I24: Verano | J24: Canon: obra clave de la literatura | K24: Sí | M24: Pendiente · le interesa
A25: 1 · Imprescindible | B25: 150 | C25: Night | D25: La noche | E25: Elie Wiesel | F25: 1958 | G25: Memorias | H25: Memorias / Holocausto | I25: Invierno | J25: Breve y esencial
A26: 1 · Imprescindible | B26: 154 | C26: Of Mice and Men | D26: De ratones y hombres | E26: John Steinbeck | F26: 1937 | G26: Novela corta | H26: Drama | I26: Verano | J26: Breve: se lee en una tarde
A27: 1 · Imprescindible | B27: 157 | C27: One Flew Over the Cuckoo's Nest | D27: Alguien voló sobre el nido del cuco | E27: Ken Kesey | F27: 1962 | G27: Novela | H27: Drama | I27: Otoño | J27: Canon: obra clave de la literatura
A28: 1 · Imprescindible | B28: 158 | C28: One Hundred Years of Solitude | D28: Cien años de soledad | E28: Gabriel García Márquez | F28: 1967 | G28: Novela | H28: Realismo mágico | I28: Verano | J28: Canon: obra clave de la literatura | K28: Sí | L28: Leído | M28: Pendiente · le interesa
A29: 1 · Imprescindible | B29: 166 | C29: Pride and Prejudice | D29: Orgullo y prejuicio | E29: Jane Austen | F29: 1813 | G29: Novela | H29: Romance | I29: Primavera | J29: Canon: obra clave de la literatura | K29: Sí | M29: Leído
A30: 1 · Imprescindible | B30: 174 | C30: Rebecca | D30: Rebeca | E30: Daphne du Maurier | F30: 1938 | G30: Novela | H30: Gótico / suspense | I30: Otoño | J30: Canon: obra clave de la literatura
A31: 1 · Imprescindible | B31: 193 | C31: Slaughterhouse-Five | D31: Matadero cinco | E31: Kurt Vonnegut | F31: 1969 | G31: Novela | H31: Ciencia ficción / antibélica | I31: Invierno | J31: Canon: obra clave de la literatura
A32: 1 · Imprescindible | B32: 205 | C32: The Sun Also Rises | D32: Fiesta | E32: Ernest Hemingway | F32: 1926 | G32: Novela | H32: Generación perdida | I32: Verano | J32: Canon: obra clave de la literatura
A33: 1 · Imprescindible | B33: 206 | C33: Swann's Way | D33: Por el camino de Swann | E33: Marcel Proust | F33: 1913 | G33: Novela | H33: Modernismo | I33: Primavera | J33: Canon: obra clave de la literatura
A34: 1 · Imprescindible | B34: 217 | C34: The Bell Jar | D34: La campana de cristal | E34: Sylvia Plath | F34: 1963 | G34: Novela | H34: Autoficción | I34: Verano | J34: Canon: obra clave de la literatura | K34: Sí | M34: Pendiente · en casa
A35: 1 · Imprescindible | B35: 222 | C35: The Catcher in the Rye | D35: El guardián entre el centeno | E35: J. D. Salinger | F35: 1951 | G35: Novela | H35: Coming-of-age | I35: Invierno | J35: Canon: obra clave de la literatura | K35: Sí | L35: Leído | M35: Pendiente · le interesa
A36: 1 · Imprescindible | B36: 235 | C36: The Divine Comedy | D36: La Divina Comedia | E36: Dante Alighieri | F36: c. 1321 | G36: Poesía | H36: Épica / alegoría | I36: Primavera | J36: Incluye el Infierno (nº 112) | K36: Sí | M36: Pendiente · en casa
A37: 1 · Imprescindible | B37: 244 | C37: The God of Small Things | D37: El dios de las pequeñas cosas | E37: Arundhati Roy | F37: 1997 | G37: Novela | H37: Drama familiar | I37: Verano | J37: Canon: obra clave de la literatura
A38: 1 · Imprescindible | B38: 248 | C38: The Grapes of Wrath | D38: Las uvas de la ira | E38: John Steinbeck | F38: 1939 | G38: Novela | H38: Drama social | I38: Verano | J38: Canon: obra clave de la literatura | K38: Sí | M38: Pendiente · le interesa
A39: 1 · Imprescindible | B39: 249 | C39: The Great Gatsby | D39: El gran Gatsby | E39: F. Scott Fitzgerald | F39: 1925 | G39: Novela | H39: Clásico / era del jazz | I39: Verano | J39: Canon: obra clave de la literatura | K39: Sí | L39: Leído | M39: Pendiente · le interesa
A40: 1 · Imprescindible | B40: 253 | C40: The House of the Spirits | D40: La casa de los espíritus | E40: Isabel Allende | F40: 1982 | G40: Novela | H40: Realismo mágico | I40: Otoño | J40: Canon: obra clave de la literatura | K40: Sí | L40: Leído | M40: Releer
...

Sheet Lista
A1: Nº | B1: Obra | C1: Título en español | D1: Autor | E1: Año (1ª publ.) | F1: Tipo | G1: Género | H1: Estación | I1: País del autor | J1: Idioma original | K1: Premios destacados | L1: Notas / erratas del PDF | M1: Leído | N1: Nivel criba
A2: 1 | B2: 1984 | D2: George Orwell | E2: 1949 | F2: Novela | G2: Distopía | H2: Invierno | I2: Reino Unido | J2: Inglés | N2: 1 · Imprescindible
A3: 2 | B3: A Bolt from the Blue and Other Essays | D3: Mary McCarthy | E3: 2002 | F3: Ensayo | G3: Ensayo literario | H3: Otoño | I3: EE. UU. | J3: Inglés | L3: Recopilación póstuma | N3: 6 · Prescindible
A4: 3 | B4: A Christmas Carol | C4: Canción de Navidad | D4: Charles Dickens | E4: 1843 | F4: Novela corta | G4: Clásico navideño / fantasía | H4: Invierno | I4: Reino Unido | J4: Inglés | N4: 2 · Muy recomendable
A5: 4 | B5: A Clockwork Orange | C5: La naranja mecánica | D5: Anthony Burgess | E5: 1962 | F5: Novela | G5: Distopía | H5: Otoño | I5: Reino Unido | J5: Inglés | N5: 2 · Muy recomendable
A6: 5 | B6: The Comedy of Errors | C6: La comedia de las equivocaciones | D6: William Shakespeare | E6: c. 1594 | F6: Teatro | G6: Comedia | H6: Primavera | I6: Reino Unido | J6: Inglés | L6: En el PDF: "A Comedy of Errors" | N6: 4 · Interesante
A7: 6 | B7: A Confederacy of Dunces | C7: La conjura de los necios | D7: John Kennedy Toole | E7: 1980 | F7: Novela | G7: Comedia / sátira | H7: Verano | I7: EE. UU. | J7: Inglés | K7: Pulitzer de Ficción 1981 | L7: Publicada póstumamente | N7: 1 · Imprescindible
A8: 7 | B8: A Heartbreaking Work of Staggering Genius | C8: Una historia conmovedora, asombrosa y genial | D8: Dave Eggers | E8: 2000 | F8: Memorias | G8: Memorias | H8: Primavera | I8: EE. UU. | J8: Inglés | K8: Finalista Pulitzer 2001 | N8: 4 · Interesante
A9: 8 | B9: A Monetary History of the United States, 1867–1960 | D9: Milton Friedman y Anna J. Schwartz | E9: 1963 | F9: No ficción | G9: Economía | H9: Otoño | I9: EE. UU. | J9: Inglés | L9: El PDF omite a la coautora Anna Schwartz | N9: 7 · Descartable
A10: 9 | B10: A Month of Sundays: Searching for the Spirit and My Sister | D10: Julie Mars | E10: 2004 | F10: Memorias | G10: Memorias | H10: Otoño | I10: EE. UU. | J10: Inglés | N10: 6 · Prescindible
A11: 10 | B11: A Moveable Feast | C11: París era una fiesta | D11: Ernest Hemingway | E11: 1964 | F11: Memorias | G11: Memorias / París años 20 | H11: Primavera | I11: EE. UU. | J11: Inglés | L11: Publicada póstumamente | N11: 2 · Muy recomendable
A12: 11 | B12: A Passage to India | C12: Pasaje a la India | D12: E. M. Forster | E12: 1924 | F12: Novela | G12: Clásico / colonialismo | H12: Verano | I12: Reino Unido | J12: Inglés | N12: 2 · Muy recomendable
A13: 12 | B13: A Quiet Storm | D13: Rachel Howzell Hall | E13: 2002 | F13: Novela | G13: Drama familiar | H13: Otoño | I13: EE. UU. | J13: Inglés | N13: 6 · Prescindible
A14: 13 | B14: A Room of One's Own | C14: Una habitación propia | D14: Virginia Woolf | E14: 1929 | F14: Ensayo | G14: Ensayo feminista | H14: Otoño | I14: Reino Unido | J14: Inglés | N14: 1 · Imprescindible
A15: 14 | B15: A Room with a View | C15: Una habitación con vistas | D15: E. M. Forster | E15: 1908 | F15: Novela | G15: Romance / costumbres | H15: Primavera | I15: Reino Unido | J15: Inglés | N15: 2 · Muy recomendable
A16: 15 | B16: A Separate Peace | D16: John Knowles | E16: 1959 | F16: Novela | G16: Coming-of-age | H16: Verano | I16: EE. UU. | J16: Inglés | N16: 3 · Recomendable
A17: 16 | B17: A Streetcar Named Desire | C17: Un tranvía llamado deseo | D17: Tennessee Williams | E17: 1947 | F17: Teatro | G17: Drama | H17: Verano | I17: EE. UU. | J17: Inglés | K17: Pulitzer de Teatro 1948 | L17: En el PDF: "Desiree" | N17: 2 · Muy recomendable
A18: 17 | B18: A Tale of Two Cities | C18: Historia de dos ciudades | D18: Charles Dickens | E18: 1859 | F18: Novela | G18: Histórica | H18: Otoño | I18: Reino Unido | J18: Inglés | N18: 2 · Muy recomendable
A19: 18 | B19: A Tree Grows in Brooklyn | C19: Un árbol crece en Brooklyn | D19: Betty Smith | E19: 1943 | F19: Novela | G19: Coming-of-age | H19: Verano | I19: EE. UU. | J19: Inglés | N19: 2 · Muy recomendable
A20: 19 | B20: Alice's Adventures in Wonderland | C20: Alicia en el país de las maravillas | D20: Lewis Carroll | E20: 1865 | F20: Infantil | G20: Fantasía | H20: Primavera | I20: Reino Unido | J20: Inglés | N20: 3 · Recomendable
A21: 20 | B21: An American Tragedy | C21: Una tragedia americana | D21: Theodore Dreiser | E21: 1925 | F21: Novela | G21: Drama / crimen | H21: Verano | I21: EE. UU. | J21: Inglés | N21: 3 · Recomendable
A22: 21 | B22: Angela's Ashes | C22: Las cenizas de Ángela | D22: Frank McCourt | E22: 1996 | F22: Memorias | G22: Memorias | H22: Invierno | I22: Irlanda / EE. UU. | J22: Inglés | K22: Pulitzer de Biografía 1997 | N22: 2 · Muy recomendable
A23: 22 | B23: Anna Karenina | C23: Ana Karenina | D23: León Tolstói | E23: 1878 | F23: Novela | G23: Clásico / drama romántico | H23: Invierno | I23: Rusia | J23: Ruso | N23: 1 · Imprescindible
A24: 23 | B24: The Diary of a Young Girl | C24: Diario de Ana Frank | D24: Anne Frank | E24: 1947 | F24: Diario | G24: Diario / Holocausto | H24: Invierno | I24: Alemania / Países Bajos | J24: Neerlandés | N24: 2 · Muy recomendable
A25: 24 | B25: The Archidamian War | D25: Donald Kagan | E25: 1974 | F25: Historia | G25: Historia antigua | H25: Otoño | I25: EE. UU. | J25: Inglés | L25: 2º de sus 4 volúmenes sobre la Guerra del Peloponeso (ver 238, 282, 284) | N25: 7 · Descartable
A26: 25 | B26: As I Lay Dying | C26: Mientras agonizo | D26: William Faulkner | E26: 1930 | F26: Novela | G26: Modernismo / gótico sureño | H26: Verano | I26: EE. UU. | J26: Inglés | N26: 1 · Imprescindible
A27: 26 | B27: Atonement | C27: Expiación | D27: Ian McEwan | E27: 2001 | F27: Novela | G27: Drama / histórica | H27: Verano | I27: Reino Unido | J27: Inglés | K27: Finalista Booker 2001 | N27: 2 · Muy recomendable
A28: 27 | B28: Autobiography of a Face | D28: Lucy Grealy | E28: 1994 | F28: Memorias | G28: Memorias | H28: Otoño | I28: EE. UU. / Irlanda | J28: Inglés | N28: 4 · Interesante
A29: 28 | B29: Babe: The Gallant Pig | C29: Babe, el cerdito valiente | D29: Dick King-Smith | E29: 1983 | F29: Infantil | G29: Infantil | H29: Primavera | I29: Reino Unido | J29: Inglés | L29: Título original en UK: "The Sheep-Pig" | N29: 6 · Prescindible
A30: 29 | B30: Backlash: The Undeclared War Against American Women | C30: Reacción: la guerra no declarada contra la mujer moderna | D30: Susan Faludi | E30: 1991 | F30: Ensayo | G30: Ensayo feminista | H30: Otoño | I30: EE. UU. | J30: Inglés | K30: National Book Critics Circle 1991 | N30: 5 · Si os apetece
A31: 30 | B31: Balzac and the Little Chinese Seamstress | C31: Balzac y la joven costurera china | D31: Dai Sijie | E31: 2000 | F31: Novela | G31: Histórica | H31: Primavera | I31: China / Francia | J31: Francés | N31: 3 · Recomendable
A32: 31 | B32: Bel Canto | C32: Bel canto | D32: Ann Patchett | E32: 2001 | F32: Novela | G32: Drama | H32: Verano | I32: EE. UU. | J32: Inglés | K32: Orange Prize 2002; PEN/Faulkner 2002 | N32: 3 · Recomendable
A33: 32 | B33: Beloved | D33: Toni Morrison | E33: 1987 | F33: Novela | G33: Histórica / gótico | H33: Invierno | I33: EE. UU. | J33: Inglés | K33: Pulitzer de Ficción 1988 | N33: 1 · Imprescindible
A34: 33 | B34: Beowulf: A New Verse Translation | C34: Beowulf | D34: Anónimo (trad. Seamus Heaney) | E34: 1999 | F34: Poesía | G34: Épica | H34: Invierno | I34: Inglaterra (anónimo) / Irlanda (trad.) | J34: Inglés antiguo | K34: Whitbread Book of the Year 1999 (trad.) | L34: Original anónimo, entre los s. VIII y XI; el año es el de la traducción | N34: 3 · Recomendable
A35: 34 | B35: Bitch: In Praise of Difficult Women | D35: Elizabeth Wurtzel | E35: 1998 | F35: Ensayo | G35: Ensayo feminista | H35: Otoño | I35: EE. UU. | J35: Inglés | N35: 5 · Si os apetece
A36: 35 | B36: Brave New World | C36: Un mundo feliz | D36: Aldous Huxley | E36: 1932 | F36: Novela | G36: Distopía | H36: Primavera | I36: Reino Unido | J36: Inglés | N36: 1 · Imprescindible
A37: 36 | B37: Brick Lane | D37: Monica Ali | E37: 2003 | F37: Novela | G37: Ficción contemporánea | H37: Verano | I37: Reino Unido / Bangladés | J37: Inglés | K37: Finalista Booker 2003 | N37: 3 · Recomendable
A38: 37 | B38: Brigadoon | D38: Alan Jay Lerner (libreto) y Frederick Loewe (música) | E38: 1947 | F38: Teatro (musical) | G38: Musical / fantasía | H38: Primavera | I38: EE. UU. | J38: Inglés | L38: En el PDF: "Bridgadoon" | N38: 7 · Descartable
A39: 38 | B39: Candide | C39: Cándido, o el optimismo | D39: Voltaire | E39: 1759 | F39: Novela | G39: Sátira filosófica | H39: Primavera | I39: Francia | J39: Francés | N39: 1 · Imprescindible
A40: 39 | B40: Carrie | D40: Stephen King | E40: 1974 | F40: Novela | G40: Terror | H40: Primavera | I40: EE. UU. | J40: Inglés | L40: Primera novela publicada de King | N40: 4 · Interesante
...

Sheet Resumen
A1: Rory Gilmore Reading Challenge · resumen
A3: Estación | B3: Obras | C3: Leídas | D3: % del total
A4: Primavera | B4: =COUNTIF(Lista!$H$2:$H$352,A4) -> 69 | C4: =COUNTIFS(Lista!$H$2:$H$352,A4,Lista!$M$2:$M$352,"Sí") -> 0 | D4: =B4/$B$8 -> 0.1965812
A5: Verano | B5: =COUNTIF(Lista!$H$2:$H$352,A5) -> 108 | C5: =COUNTIFS(Lista!$H$2:$H$352,A5,Lista!$M$2:$M$352,"Sí") -> 0 | D5: =B5/$B$8 -> 0.30769231
A6: Otoño | B6: =COUNTIF(Lista!$H$2:$H$352,A6) -> 108 | C6: =COUNTIFS(Lista!$H$2:$H$352,A6,Lista!$M$2:$M$352,"Sí") -> 0 | D6: =B6/$B$8 -> 0.30769231
A7: Invierno | B7: =COUNTIF(Lista!$H$2:$H$352,A7) -> 66 | C7: =COUNTIFS(Lista!$H$2:$H$352,A7,Lista!$M$2:$M$352,"Sí") -> 0 | D7: =B7/$B$8 -> 0.18803419
A8: Total | B8: =SUM(B4:B7) -> 351 | C8: =SUM(C4:C7) -> 0 | D8: =SUM(D4:D7) -> 1
A10: Tipo | B10: Obras | C10: Leídas
A11: Novela | B11: =COUNTIF(Lista!$F$2:$F$352,A11) -> 169 | C11: =COUNTIFS(Lista!$F$2:$F$352,A11,Lista!$M$2:$M$352,"Sí") -> 0
A12: Memorias | B12: =COUNTIF(Lista!$F$2:$F$352,A12) -> 27 | C12: =COUNTIFS(Lista!$F$2:$F$352,A12,Lista!$M$2:$M$352,"Sí") -> 0
A13: No ficción | B13: =COUNTIF(Lista!$F$2:$F$352,A13) -> 24 | C13: =COUNTIFS(Lista!$F$2:$F$352,A13,Lista!$M$2:$M$352,"Sí") -> 0
A14: Teatro | B14: =COUNTIF(Lista!$F$2:$F$352,A14) -> 21 | C14: =COUNTIFS(Lista!$F$2:$F$352,A14,Lista!$M$2:$M$352,"Sí") -> 0
A15: Ensayo | B15: =COUNTIF(Lista!$F$2:$F$352,A15) -> 17 | C15: =COUNTIFS(Lista!$F$2:$F$352,A15,Lista!$M$2:$M$352,"Sí") -> 0
A16: Infantil | B16: =COUNTIF(Lista!$F$2:$F$352,A16) -> 14 | C16: =COUNTIFS(Lista!$F$2:$F$352,A16,Lista!$M$2:$M$352,"Sí") -> 0
A17: Poesía | B17: =COUNTIF(Lista!$F$2:$F$352,A17) -> 13 | C17: =COUNTIFS(Lista!$F$2:$F$352,A17,Lista!$M$2:$M$352,"Sí") -> 0
A18: Novela corta | B18: =COUNTIF(Lista!$F$2:$F$352,A18) -> 8 | C18: =COUNTIFS(Lista!$F$2:$F$352,A18,Lista!$M$2:$M$352,"Sí") -> 0
A19: Relatos | B19: =COUNTIF(Lista!$F$2:$F$352,A19) -> 7 | C19: =COUNTIFS(Lista!$F$2:$F$352,A19,Lista!$M$2:$M$352,"Sí") -> 0
A20: Biografía | B20: =COUNTIF(Lista!$F$2:$F$352,A20) -> 6 | C20: =COUNTIFS(Lista!$F$2:$F$352,A20,Lista!$M$2:$M$352,"Sí") -> 0
A21: Historia | B21: =COUNTIF(Lista!$F$2:$F$352,A21) -> 6 | C21: =COUNTIFS(Lista!$F$2:$F$352,A21,Lista!$M$2:$M$352,"Sí") -> 0
A22: Cuento | B22: =COUNTIF(Lista!$F$2:$F$352,A22) -> 4 | C22: =COUNTIFS(Lista!$F$2:$F$352,A22,Lista!$M$2:$M$352,"Sí") -> 0
... A40: Poesía / relatos | B40: =COUNTIF(Lista!$F$2:$F$352,A40) -> 1 | C40: =COUNTIFS(Lista!$F$2:$F$352,A40,Lista!$M$2:$M$352,"Sí") -> 0
A42: Progreso total | B42: =COUNTIF(Lista!$M$2:$M$352,"Sí")&" / "&COUNTA(Lista!$A$2:$A$352) -> 0 / 351
A44: Notas
A45: Datos del PDF de The Gilmore Book Club (351 entradas). Títulos y autores corregidos; la errata original queda en la columna Notas.
A46: Año = primera publicación del original (para traducciones, antologías o guías, el de esa edición). 'c.' = fecha aproximada.
A47: Título en español solo cuando existe una edición española conocida; si está vacío, no se ha podido confirmar.
A48: Estación = la que mejor le pega a cada obra por ambientación o tono. Es subjetiva y está pensada para repartir después.
A49: Columna Leído: desplegable Sí / No / Leyendo. Alimenta los contadores de esta hoja.
A50: Ojo: 225 y 226 son el mismo libro; 112 (Inferno) forma parte de 235 (La Divina Comedia).
A52: Criba por nivel
A53: Nivel | B53: Obras | C53: Sí | D53: Quizá | E53: No | F53: Sin decidir
A54: 1 · Imprescindible | B54: =COUNTIF(Criba!$A$2:$A$352,A54) -> 50 | C54: =COUNTIFS(Criba!$A$2:$A$352,$A54,Criba!$K$2:$K$352,"Sí") -> 33 | D54: =COUNTIFS(Criba!$A$2:$A$352,$A54,Criba!$K$2:$K$352,"Quizá") -> 0 | E54: =COUNTIFS(Criba!$A$2:$A$352,$A54,Criba!$K$2:$K$352,"No") -> 0 | F54: =B54-C54-D54-E54 -> 17
A55: 2 · Muy recomendable | B55: =COUNTIF(Criba!$A$2:$A$352,A55) -> 50 | C55: =COUNTIFS(Criba!$A$2:$A$352,$A55,Criba!$K$2:$K$352,"Sí") -> 20 | D55: =COUNTIFS(Criba!$A$2:$A$352,$A55,Criba!$K$2:$K$352,"Quizá") -> 0 | E55: =COUNTIFS(Criba!$A$2:$A$352,$A55,Criba!$K$2:$K$352,"No") -> 0 | F55: =B55-C55-D55-E55 -> 30
A56: 3 · Recomendable | B56: =COUNTIF(Criba!$A$2:$A$352,A56) -> 50 | C56: =COUNTIFS(Criba!$A$2:$A$352,$A56,Criba!$K$2:$K$352,"Sí") -> 12 | D56: =COUNTIFS(Criba!$A$2:$A$352,$A56,Criba!$K$2:$K$352,"Quizá") -> 0 | E56: =COUNTIFS(Criba!$A$2:$A$352,$A56,Criba!$K$2:$K$352,"No") -> 0 | F56: =B56-C56-D56-E56 -> 38
A57: 4 · Interesante | B57: =COUNTIF(Criba!$A$2:$A$352,A57) -> 50 | C57: =COUNTIFS(Criba!$A$2:$A$352,$A57,Criba!$K$2:$K$352,"Sí") -> 4 | D57: =COUNTIFS(Criba!$A$2:$A$352,$A57,Criba!$K$2:$K$352,"Quizá") -> 0 | E57: =COUNTIFS(Criba!$A$2:$A$352,$A57,Criba!$K$2:$K$352,"No") -> 0 | F57: =B57-C57-D57-E57 -> 46
A58: 5 · Si os apetece | B58: =COUNTIF(Criba!$A$2:$A$352,A58) -> 50 | C58: =COUNTIFS(Criba!$A$2:$A$352,$A58,Criba!$K$2:$K$352,"Sí") -> 5 | D58: =COUNTIFS(Criba!$A$2:$A$352,$A58,Criba!$K$2:$K$352,"Quizá") -> 0 | E58: =COUNTIFS(Criba!$A$2:$A$352,$A58,Criba!$K$2:$K$352,"No") -> 0 | F58: =B58-C58-D58-E58 -> 45
A59: 6 · Prescindible | B59: =COUNTIF(Criba!$A$2:$A$352,A59) -> 50 | C59: =COUNTIFS(Criba!$A$2:$A$352,$A59,Criba!$K$2:$K$352,"Sí") -> 2 | D59: =COUNTIFS(Criba!$A$2:$A$352,$A59,Criba!$K$2:$K$352,"Quizá") -> 0 | E59: =COUNTIFS(Criba!$A$2:$A$352,$A59,Criba!$K$2:$K$352,"No") -> 0 | F59: =B59-C59-D59-E59 -> 48
A60: 7 · Descartable | B60: =COUNTIF(Criba!$A$2:$A$352,A60) -> 51 | C60: =COUNTIFS(Criba!$A$2:$A$352,$A60,Criba!$K$2:$K$352,"Sí") -> 0 | D60: =COUNTIFS(Criba!$A$2:$A$352,$A60,Criba!$K$2:$K$352,"Quizá") -> 0 | E60: =COUNTIFS(Criba!$A$2:$A$352,$A60,Criba!$K$2:$K$352,"No") -> 0 | F60: =B60-C60-D60-E60 -> 51
A61: Total | B61: =SUM(B54:B60) -> 351 | C61: =SUM(C54:C60) -> 76 | D61: =SUM(D54:D60) -> 0 | E61: =SUM(E54:E60) -> 0 | F61: =SUM(F54:F60) -> 275
